Workbook

Sheet ReadMe
A1: Australia Post Commercial Postcode File → Excel (February 2026)
A3: How to use
A4: • Go to the Postcodes sheet and use the filter arrows to search by Place, State, Postcode, or Category.
A5: • Category shows the AusPost classification: "Delivery Area", "Post Office Boxes", or "LVR" (Large Volume Receiver).
A6: • Comment includes detail notes from the commercial file (e.g. "PO BOXES", "GPO BOXES", council names).
A7: • For single postcode lookups use the Search sheet. For bulk lists use Shipping_Planner.
A9: Source
A10: Australia Post Standard Postcode File (PC001), commercial release dated 18 Feb 2026.
A11: This replaces the earlier PDF-scraped version (September 2025 booklet) with the official commercial data file.
A12: The commercial file provides 2941 unique postcodes and structured Category/Comment fields.
A14: MMM integration (MMM 2023 / POA 2021)
A15: • The Postcodes sheet includes MMM columns joined by Postcode (POA 2021).
... A78: • All formula-driven — no manual entry needed.

Sheet Dashboard
A1: NUAA Postal NSP — Shipping Reference Dashboard
A2: Australia Post Commercial Postcode File (PC001) with MMM 2023 classifications
A3: Version 2.0 | Data: 18 Feb 2026 | Source: AusPost PC001 + DoH MMM 2023 / POA 2021
A5: Coverage Summary
A6: Total unique postcodes | B6: 2941
A7: Total postcode × state combinations | B7: 2957
A8: Postcodes with MMM 2023 (POA concordance) | B8: 2657
A9: Postcodes assigned via PO Box/LVR metro range | B9: 245
A10: Postcodes assigned via nearest neighbour | B10: 55
A11: Shipping_MMM coverage | B11: 100% (2,957 / 2,957)
A13: Postcodes by Shipping Zone
A14: Zone | B14: Zone Name | C14: MMM Categories | D14: Postcodes | E14: % of Total | F14: PO Box-Only in Zone
A15: 1 | B15: Metro | C15: MMM1 | D15: 1167 | E15: 39.7% | F15: 242
A16: 2 | B16: Regional | C16: MMM2–3 | D16: 303 | E16: 10.3% | F16: 27
A17: 3 | B17: Rural | C17: MMM4–5 | D17: 1098 | E17: 37.3% | F17: 19
A18: 4 | B18: Remote | C18: MMM6–7 | D18: 373 | E18: 12.7% | F18: 7
B19: Total | D19: 2941 | E19: 100% | F19: 295
A21: Postcodes by State × Shipping Zone
A22: State | B22: Zone 1 | C22: Zone 2 | D22: Zone 3 | E22: Zone 4 | F22: Total
A23: NSW | B23: 370 | C23: 44 | D23: 269 | E23: 34 | F23: 717
A24: VIC | B24: 278 | C24: 84 | D24: 371 | E24: 13 | F24: 746
A25: QLD | B25: 159 | C25: 43 | D25: 152 | E25: 96 | F25: 450
A26: SA | B26: 127 | C26: 33 | D26: 132 | E26: 58 | F26: 350
A27: WA | B27: 206 | C27: 32 | D27: 115 | E27: 138 | F27: 491
A28: TAS | B28: – | C28: 44 | D28: 62 | E28: 14 | F28: 120
A29: NT | B29: – | C29: 22 | D29: 5 | E29: 24 | F29: 51
A30: ACT | B30: 27 | C30: 2 | D30: 3 | E30: – | F30: 32
A31: Total | B31: 1167 | C31: 303 | D31: 1098 | E31: 373 | F31: 2941
A33: Sheet Guide
A34: Sheet | B34: Purpose
A35: Dashboard | B35: This sheet. Summary statistics and cross-tabs.
A36: Search | B36: Single postcode lookup with MMM, zone, and PO Box flags.
A37: Postcodes | B37: Full place-level listing (16,555 rows) from AusPost PC001 with MMM data.
A38: Postcode_Summary | B38: One row per postcode×state with Shipping_MMM, zone classification, and audit trail.
A39: Shopify_Zones | B39: Copy-paste postcode lists for Shopify shipping zone configuration.
A40: Shipping_Planner | B40: Paste up to 1,000 postcodes for bulk zone/MMM lookup.
A41: Shipping_Zones | B41: Editable zone definitions: MMM→zone mapping, surcharges, extra days.
A42: State_Ranges | B42: Postcode ranges by state (reference).
A43: MMM_2023_Lookup | B43: MMM category labels (reference).
A44: POA_21_MMM_23 | B44: Raw POA 2021 × MMM 2023 concordance (source data).
...

Sheet Search
A1: Postcode & Suburb Lookup
A3: Search by | B3: Postcode
A4: Enter value | B4: 2560
A5: State (optional)
A7: Status | B7: =IF($B$4="","Enter a postcode or suburb name above.",IF($B$3="Postcode",IF(COUNTIF(Postcode_Summary!$A:$A,$B$4)>0,"✓ Found","✗ Postcode not found. Check the number and try again."),IF($B$3="Suburb",IF(COUNTIF(Postcodes!$A:$A,"*"&$B$4&"*")>0,COUNTIF(Postcodes!$A:$A,"*"&$B$4&"*")&" match(es) found","✗ Suburb not found. Try a different spelling or check the Postcodes sheet."),"Select Postcode or Suburb above.")))
A8: Resolved Key | B8: =IF($B$4="","",IF($B$3="Postcode",IF(COUNTIF(Postcode_Summary!$A:$A,$B$4)=0,"",IF($B$5<>"",$B$4&"|"&$B$5,$B$4&"|"&INDEX(Postcode_Summary!$B$2:$B$99999,MATCH($B$4,Postcode_Summary!$A$2:$A$99999,0)))),IF(COUNTIF(Postcodes!$A:$A,"*"&$B$4&"*")=0,"",INDEX(Postcodes!$C:$C,MATCH("*"&$B$4&"*",Postcodes!$A:$A,0))&"|"&INDEX(Postcodes!$B:$B,MATCH("*"&$B$4&"*",Postcodes!$A:$A,0)))))
A10: Results
A11: Postcode | B11: =IF($B$8="","",INDEX(Postcode_Summary!$A$2:$A$99999,MATCH($B$8,Postcode_Summary!$C$2:$C$99999,0)))
A12: State | B12: =IF($B$8="","",INDEX(Postcode_Summary!$B$2:$B$99999,MATCH($B$8,Postcode_Summary!$C$2:$C$99999,0)))
A13: Representative Place | B13: =IF($B$8="","",INDEX(Postcode_Summary!$D$2:$D$99999,MATCH($B$8,Postcode_Summary!$C$2:$C$99999,0)))
A14: Example Places | B14: =IF($B$8="","",INDEX(Postcode_Summary!$E$2:$E$99999,MATCH($B$8,Postcode_Summary!$C$2:$C$99999,0)))
A15: Shipping MMM | B15: =IF($B$8="","",INDEX(Postcode_Summary!$Q$2:$Q$99999,MATCH($B$8,Postcode_Summary!$C$2:$C$99999,0)))
A16: MMM Classification | B16: =IF($B$8="","",INDEX(Postcode_Summary!$R$2:$R$99999,MATCH($B$8,Postcode_Summary!$C$2:$C$99999,0)))
A17: Shipping Zone | B17: =IF($B$15="","",VLOOKUP($B$15,Shipping_Zones!$A$7:$B$14,2,FALSE()))
A18: Zone Name | B18: =IF($B$17="","",INDEX(Shipping_Zones!$B$2:$B$5,MATCH($B$17,Shipping_Zones!$A$2:$A$5,0)))
A19: PO Box Flagged? | B19: =IF($B$8="","",INDEX(Postcode_Summary!$H$2:$H$99999,MATCH($B$8,Postcode_Summary!$C$2:$C$99999,0)))
A20: MMM Breakdown | B20: =IF($B$8="","",INDEX(Postcode_Summary!$N$2:$N$99999,MATCH($B$8,Postcode_Summary!$C$2:$C$99999,0)))
A21: MMM Source | B21: =IF($B$8="","",INDEX(Postcode_Summary!$S$2:$S$99999,MATCH($B$8,Postcode_Summary!$C$2:$C$99999,0)))
A22: NSW Local Health District | B22: =IF($B$8="","",INDEX(Postcode_Summary!$T$2:$T$99999,MATCH($B$8,Postcode_Summary!$C$2:$C$99999,0)))
A23: Population (ERP 2021) | B23: =IF($B$8="","",INDEX(Postcode_Summary!$V$2:$V$99999,MATCH($B$8,Postcode_Summary!$C$2:$C$99999,0)))
A24: Indigenous Population | B24: =IF($B$8="","",INDEX(Postcode_Summary!$W$2:$W$99999,MATCH($B$8,Postcode_Summary!$C$2:$C$99999,0)))
A25: Indigenous % | B25: =IF($B$8="","",INDEX(Postcode_Summary!$X$2:$X$99999,MATCH($B$8,Postcode_Summary!$C$2:$C$99999,0)))
A26: SEIFA Disadvantage Score | B26: =IF($B$8="","",INDEX(Postcode_Summary!$Y$2:$Y$99999,MATCH($B$8,Postcode_Summary!$C$2:$C$99999,0)))
A27: SEIFA Disadvantage Decile | B27: =IF($B$8="","",INDEX(Postcode_Summary!$Z$2:$Z$99999,MATCH($B$8,Postcode_Summary!$C$2:$C$99999,0)))
A28: Disadvantage Level | B28: =IF($B$27="","",IF($B$27<=2,"Most disadvantaged (bottom 20%)",IF($B$27<=4,"Below average",IF($B$27<=6,"Average",IF($B$27<=8,"Above average","Least disadvantaged (top 20%)")))))
A29: PHN Code | B29: =IF($B$8="","",IFERROR(INDEX(Postcode_Summary!$AD$2:$AD$99999,MATCH($B$8,Postcode_Summary!$C$2:$C$99999,0)),""))
A30: PHN Name | B30: =IF($B$8="","",IFERROR(INDEX(Postcode_Summary!$AE$2:$AE$99999,MATCH($B$8,Postcode_Summary!$C$2:$C$99999,0)),""))
A31: Remoteness Area | B31: =IF($B$8="","",IFERROR(INDEX(Postcode_Summary!$AB$2:$AB$99999,MATCH($B$8,Postcode_Summary!$C$2:$C$99999,0)),""))
A32: PHN Split Note | B32: =IF($B$8="","",IFERROR(INDEX(Postcode_Summary!$AG$2:$AG$99999,MATCH($B$8,Postcode_Summary!$C$2:$C$99999,0)),""))
A34: Notes | B34: SEIFA Decile: 1=most disadvantaged 10% nationally. Indigenous % from Census 2021. PO Box postcodes may lack Census data.
A35: Tip | B35: For bulk planning, use the Shipping_Planner sheet (paste postcodes in column A).

Sheet Shipping_Planner
A1: Shipping Planner (paste a list of postcodes; get MMM + shipping zone + flags)
A3: Inputs
A4: Use default zone settings? | B4: Yes
A6: Paste Postcodes Here ↓
A7: Postcode | B7: State (optional) | C7: Key | D7: Rep Place | E7: MMM Primary | F7: MMM Label | G7: Zone | H7: PO Box flagged | I7: Extra Days | J7: Surcharge % | K7: Notes | L7: NSW LHD | M7: Indigenous % | N7: SEIFA Decile | O7: Population | P7: PHN Code | Q7: PHN Name | R7: Remoteness Area
C8: =IF($A8="","",IFERROR(IF($B8<>"",$A8&"|"&$B8,$A8&"|"&INDEX(Postcode_Summary!$B$2:$B$99999,MATCH($A8,Postcode_Summary!$A$2:$A$99999,0))),"")) | D8: =IF($A8="","",IFERROR(INDEX(Postcode_Summary!$D$2:$D$99999,MATCH($C8,Postcode_Summary!$C$2:$C$99999,0)),IF($C8="","⚠ Postcode not recognised","⚠ State mismatch"))) | E8: =IF($A8="","",IFERROR(INDEX(Postcode_Summary!$Q$2:$Q$99999,MATCH($C8,Postcode_Summary!$C$2:$C$99999,0)),"")) | F8: =IF($A8="","",IFERROR(INDEX(Postcode_Summary!$R$2:$R$99999,MATCH($C8,Postcode_Summary!$C$2:$C$99999,0)),"")) | G8: =IF($A8="","",IFERROR(VLOOKUP($E8,Shipping_Zones!$A$7:$B$14,2,FALSE()),"")) | H8: =IF($A8="","",IFERROR(INDEX(Postcode_Summary!$H$2:$H$99999,MATCH($C8,Postcode_Summary!$C$2:$C$99999,0)),"")) | I8: =IF($A8="","",IFERROR(INDEX(Shipping_Zones!$E$2:$E$5,MATCH($G8,Shipping_Zones!$A$2:$A$5,0)),"")) | J8: =IF($A8="","",IFERROR(INDEX(Shipping_Zones!$D$2:$D$5,MATCH($G8,Shipping_Zones!$A$2:$A$5,0)),"")) | K8: =IF($A8="","",IF(IFERROR(MATCH($C8,Postcode_Summary!$C$2:$C$99999,0),"ERR")="ERR","⚠ Check postcode/state",IF($H8=TRUE(),"PO Box flagged in source data",""))) | L8: =IF($A8="","",IFERROR(INDEX(Postcode_Summary!$T$2:$T$99999,MATCH($C8,Postcode_Summary!$C$2:$C$99999,0)),"")) | M8: =IF($A8="","",IFERROR(INDEX(Postcode_Summary!$X$2:$X$99999,MATCH($C8,Postcode_Summary!$C$2:$C$99999,0)),"")) | N8: =IF($A8="","",IFERROR(INDEX(Postcode_Summary!$Z$2:$Z$99999,MATCH($C8,Postcode_Summary!$C$2:$C$99999,0)),"")) | O8: =IF($A8="","",IFERROR(INDEX(Postcode_Summary!$V$2:$V$99999,MATCH($C8,Postcode_Summary!$C$2:$C$99999,0)),"")) | P8: =IF($A8="","",IFERROR(INDEX(Postcode_Summary!$AD$2:$AD$99999,MATCH($C8,Postcode_Summary!$C$2:$C$99999,0)),"")) | Q8: =IF($A8="","",IFERROR(INDEX(Postcode_Summary!$AE$2:$AE$99999,MATCH($C8,Postcode_Summary!$C$2:$C$99999,0)),"")) | R8: =IF($A8="","",IFERROR(INDEX(Postcode_Summary!$AB$2:$AB$99999,MATCH($C8,Postcode_Summary!$C$2:$C$99999,0)),""))
C9: =IF($A9="","",IFERROR(IF($B9<>"",$A9&"|"&$B9,$A9&"|"&INDEX(Postcode_Summary!$B$2:$B$99999,MATCH($A9,Postcode_Summary!$A$2:$A$99999,0))),"")) | D9: =IF($A9="","",IFERROR(INDEX(Postcode_Summary!$D$2:$D$99999,MATCH($C9,Postcode_Summary!$C$2:$C$99999,0)),IF($C9="","⚠ Postcode not recognised","⚠ State mismatch"))) | E9: =IF($A9="","",IFERROR(INDEX(Postcode_Summary!$Q$2:$Q$99999,MATCH($C9,Postcode_Summary!$C$2:$C$99999,0)),"")) | F9: =IF($A9="","",IFERROR(INDEX(Postcode_Summary!$R$2:$R$99999,MATCH($C9,Postcode_Summary!$C$2:$C$99999,0)),"")) | G9: =IF($A9="","",IFERROR(VLOOKUP($E9,Shipping_Zones!$A$7:$B$14,2,FALSE()),"")) | H9: =IF($A9="","",IFERROR(INDEX(Postcode_Summary!$H$2:$H$99999,MATCH($C9,Postcode_Summary!$C$2:$C$99999,0)),"")) | I9: =IF($A9="","",IFERROR(INDEX(Shipping_Zones!$E$2:$E$5,MATCH($G9,Shipping_Zones!$A$2:$A$5,0)),"")) | J9: =IF($A9="","",IFERROR(INDEX(Shipping_Zones!$D$2:$D$5,MATCH($G9,Shipping_Zones!$A$2:$A$5,0)),"")) | K9: =IF($A9="","",IF(IFERROR(MATCH($C9,Postcode_Summary!$C$2:$C$99999,0),"ERR")="ERR","⚠ Check postcode/state",IF($H9=TRUE(),"PO Box flagged in source data",""))) | L9: =IF($A9="","",IFERROR(INDEX(Postcode_Summary!$T$2:$T$99999,MATCH($C9,Postcode_Summary!$C$2:$C$99999,0)),"")) | M9: =IF($A9="","",IFERROR(INDEX(Postcode_Summary!$X$2:$X$99999,MATCH($C9,Postcode_Summary!$C$2:$C$99999,0)),"")) | N9: =IF($A9="","",IFERROR(INDEX(Postcode_Summary!$Z$2:$Z$99999,MATCH($C9,Postcode_Summary!$C$2:$C$99999,0)),"")) | O9: =IF($A9="","",IFERROR(INDEX(Postcode_Summary!$V$2:$V$99999,MATCH($C9,Postcode_Summary!$C$2:$C$99999,0)),"")) | P9: =IF($A9="","",IFERROR(INDEX(Postcode_Summary!$AD$2:$AD$99999,MATCH($C9,Postcode_Summary!$C$2:$C$99999,0)),"")) | Q9: =IF($A9="","",IFERROR(INDEX(Postcode_Summary!$AE$2:$AE$99999,MATCH($C9,Postcode_Summary!$C$2:$C$99999,0)),"")) | R9: =IF($A9="","",IFERROR(INDEX(Postcode_Summary!$AB$2:$AB$99999,MATCH($C9,Postcode_Summary!$C$2:$C$99999,0)),""))
C10: =IF($A10="","",IFERROR(IF($B10<>"",$A10&"|"&$B10,$A10&"|"&INDEX(Postcode_Summary!$B$2:$B$99999,MATCH($A10,Postcode_Summary!$A$2:$A$99999,0))),"")) | D10: =IF($A10="","",IFERROR(INDEX(Postcode_Summary!$D$2:$D$99999,MATCH($C10,Postcode_Summary!$C$2:$C$99999,0)),IF($C10="","⚠ Postcode not recognised","⚠ State mismatch"))) | E10: =IF($A10="","",IFERROR(INDEX(Postcode_Summary!$Q$2:$Q$99999,MATCH($C10,Postcode_Summary!$C$2:$C$99999,0)),"")) | F10: =IF($A10="","",IFERROR(INDEX(Postcode_Summary!$R$2:$R$99999,MATCH($C10,Postcode_Summary!$C$2:$C$99999,0)),"")) | G10: =IF($A10="","",IFERROR(VLOOKUP($E10,Shipping_Zones!$A$7:$B$14,2,FALSE()),"")) | H10: =IF($A10="","",IFERROR(INDEX(Postcode_Summary!$H$2:$H$99999,MATCH($C10,Postcode_Summary!$C$2:$C$99999,0)),"")) | I10: =IF($A10="","",IFERROR(INDEX(Shipping_Zones!$E$2:$E$5,MATCH($G10,Shipping_Zones!$A$2:$A$5,0)),"")) | J10: =IF($A10="","",IFERROR(INDEX(Shipping_Zones!$D$2:$D$5,MATCH($G10,Shipping_Zones!$A$2:$A$5,0)),"")) | K10: =IF($A10="","",IF(IFERROR(MATCH($C10,Postcode_Summary!$C$2:$C$99999,0),"ERR")="ERR","⚠ Check postcode/state",IF($H10=TRUE(),"PO Box flagged in source data",""))) | L10: =IF($A10="","",IFERROR(INDEX(Postcode_Summary!$T$2:$T$99999,MATCH($C10,Postcode_Summary!$C$2:$C$99999,0)),"")) | M10: =IF($A10="","",IFERROR(INDEX(Postcode_Summary!$X$2:$X$99999,MATCH($C10,Postcode_Summary!$C$2:$C$99999,0)),"")) | N10: =IF($A10="","",IFERROR(INDEX(Postcode_Summary!$Z$2:$Z$99999,MATCH($C10,Postcode_Summary!$C$2:$C$99999,0)),"")) | O10: =IF($A10="","",IFERROR(INDEX(Postcode_Summary!$V$2:$V$99999,MATCH($C10,Postcode_Summary!$C$2:$C$99999,0)),"")) | P10: =IF($A10="","",IFERROR(INDEX(Postcode_Summary!$AD$2:$AD$99999,MATCH($C10,Postcode_Summary!$C$2:$C$99999,0)),"")) | Q10: =IF($A10="","",IFERROR(INDEX(Postcode_Summary!$AE$2:$AE$99999,MATCH($C10,Postcode_Summary!$C$2:$C$99999,0)),"")) | R10: =IF($A10="","",IFERROR(INDEX(Postcode_Summary!$AB$2:$AB$99999,MATCH($C10,Postcode_Summary!$C$2:$C$99999,0)),""))
C11: =IF($A11="","",IFERROR(IF($B11<>"",$A11&"|"&$B11,$A11&"|"&INDEX(Postcode_Summary!$B$2:$B$99999,MATCH($A11,Postcode_Summary!$A$2:$A$99999,0))),"")) | D11: =IF($A11="","",IFERROR(INDEX(Postcode_Summary!$D$2:$D$99999,MATCH($C11,Postcode_Summary!$C$2:$C$99999,0)),IF($C11="","⚠ Postcode not recognised","⚠ State mismatch"))) | E11: =IF($A11="","",IFERROR(INDEX(Postcode_Summary!$Q$2:$Q$99999,MATCH($C11,Postcode_Summary!$C$2:$C$99999,0)),"")) | F11: =IF($A11="","",IFERROR(INDEX(Postcode_Summary!$R$2:$R$99999,MATCH($C11,Postcode_Summary!$C$2:$C$99999,0)),"")) | G11: =IF($A11="","",IFERROR(VLOOKUP($E11,Shipping_Zones!$A$7:$B$14,2,FALSE()),"")) | H11: =IF($A11="","",IFERROR(INDEX(Postcode_Summary!$H$2:$H$99999,MATCH($C11,Postcode_Summary!$C$2:$C$99999,0)),"")) | I11: =IF($A11="","",IFERROR(INDEX(Shipping_Zones!$E$2:$E$5,MATCH($G11,Shipping_Zones!$A$2:$A$5,0)),"")) | J11: =IF($A11="","",IFERROR(INDEX(Shipping_Zones!$D$2:$D$5,MATCH($G11,Shipping_Zones!$A$2:$A$5,0)),"")) | K11: =IF($A11="","",IF(IFERROR(MATCH($C11,Postcode_Summary!$C$2:$C$99999,0),"ERR")="ERR","⚠ Check postcode/state",IF($H11=TRUE(),"PO Box flagged in source data",""))) | L11: =IF($A11="","",IFERROR(INDEX(Postcode_Summary!$T$2:$T$99999,MATCH($C11,Postcode_Summary!$C$2:$C$99999,0)),"")) | M11: =IF($A11="","",IFERROR(INDEX(Postcode_Summary!$X$2:$X$99999,MATCH($C11,Postcode_Summary!$C$2:$C$99999,0)),"")) | N11: =IF($A11="","",IFERROR(INDEX(Postcode_Summary!$Z$2:$Z$99999,MATCH($C11,Postcode_Summary!$C$2:$C$99999,0)),"")) | O11: =IF($A11="","",IFERROR(INDEX(Postcode_Summary!$V$2:$V$99999,MATCH($C11,Postcode_Summary!$C$2:$C$99999,0)),"")) | P11: =IF($A11="","",IFERROR(INDEX(Postcode_Summary!$AD$2:$AD$99999,MATCH($C11,Postcode_Summary!$C$2:$C$99999,0)),"")) | Q11: =IF($A11="","",IFERROR(INDEX(Postcode_Summary!$AE$2:$AE$99999,MATCH($C11,Postcode_Summary!$C$2:$C$99999,0)),"")) | R11: =IF($A11="","",IFERROR(INDEX(Postcode_Summary!$AB$2:$AB$99999,MATCH($C11,Postcode_Summary!$C$2:$C$99999,0)),""))
C12: =IF($A12="","",IFERROR(IF($B12<>"",$A12&"|"&$B12,$A12&"|"&INDEX(Postcode_Summary!$B$2:$B$99999,MATCH($A12,Postcode_Summary!$A$2:$A$99999,0))),"")) | D12: =IF($A12="","",IFERROR(INDEX(Postcode_Summary!$D$2:$D$99999,MATCH($C12,Postcode_Summary!$C$2:$C$99999,0)),IF($C12="","⚠ Postcode not recognised","⚠ State mismatch"))) | E12: =IF($A12="","",IFERROR(INDEX(Postcode_Summary!$Q$2:$Q$99999,MATCH($C12,Postcode_Summary!$C$2:$C$99999,0)),"")) | F12: =IF($A12="","",IFERROR(INDEX(Postcode_Summary!$R$2:$R$99999,MATCH($C12,Postcode_Summary!$C$2:$C$99999,0)),"")) | G12: =IF($A12="","",IFERROR(VLOOKUP($E12,Shipping_Zones!$A$7:$B$14,2,FALSE()),"")) | H12: =IF($A12="","",IFERROR(INDEX(Postcode_Summary!$H$2:$H$99999,MATCH($C12,Postcode_Summary!$C$2:$C$99999,0)),"")) | I12: =IF($A12="","",IFERROR(INDEX(Shipping_Zones!$E$2:$E$5,MATCH($G12,Shipping_Zones!$A$2:$A$5,0)),"")) | J12: =IF($A12="","",IFERROR(INDEX(Shipping_Zones!$D$2:$D$5,MATCH($G12,Shipping_Zones!$A$2:$A$5,0)),"")) | K12: =IF($A12="","",IF(IFERROR(MATCH($C12,Postcode_Summary!$C$2:$C$99999,0),"ERR")="ERR","⚠ Check postcode/state",IF($H12=TRUE(),"PO Box flagged in source data",""))) | L12: =IF($A12="","",IFERROR(INDEX(Postcode_Summary!$T$2:$T$99999,MATCH($C12,Postcode_Summary!$C$2:$C$99999,0)),"")) | M12: =IF($A12="","",IFERROR(INDEX(Postcode_Summary!$X$2:$X$99999,MATCH($C12,Postcode_Summary!$C$2:$C$99999,0)),"")) | N12: =IF($A12="","",IFERROR(INDEX(Postcode_Summary!$Z$2:$Z$99999,MATCH($C12,Postcode_Summary!$C$2:$C$99999,0)),"")) | O12: =IF($A12="","",IFERROR(INDEX(Postcode_Summary!$V$2:$V$99999,MATCH($C12,Postcode_Summary!$C$2:$C$99999,0)),"")) | P12: =IF($A12="","",IFERROR(INDEX(Postcode_Summary!$AD$2:$AD$99999,MATCH($C12,Postcode_Summary!$C$2:$C$99999,0)),"")) | Q12: =IF($A12="","",IFERROR(INDEX(Postcode_Summary!$AE$2:$AE$99999,MATCH($C12,Postcode_Summary!$C$2:$C$99999,0)),"")) | R12: =IF($A12="","",IFERROR(INDEX(Postcode_Summary!$AB$2:$AB$99999,MATCH($C12,Postcode_Summary!$C$2:$C$99999,0)),""))
C13: =IF($A13="","",IFERROR(IF($B13<>"",$A13&"|"&$B13,$A13&"|"&INDEX(Postcode_Summary!$B$2:$B$99999,MATCH($A13,Postcode_Summary!$A$2:$A$99999,0))),"")) | D13: =IF($A13="","",IFERROR(INDEX(Postcode_Summary!$D$2:$D$99999,MATCH($C13,Postcode_Summary!$C$2:$C$99999,0)),IF($C13="","⚠ Postcode not recognised","⚠ State mismatch"))) | E13: =IF($A13="","",IFERROR(INDEX(Postcode_Summary!$Q$2:$Q$99999,MATCH($C13,Postcode_Summary!$C$2:$C$99999,0)),"")) | F13: =IF($A13="","",IFERROR(INDEX(Postcode_Summary!$R$2:$R$99999,MATCH($C13,Postcode_Summary!$C$2:$C$99999,0)),"")) | G13: =IF($A13="","",IFERROR(VLOOKUP($E13,Shipping_Zones!$A$7:$B$14,2,FALSE()),"")) | H13: =IF($A13="","",IFERROR(INDEX(Postcode_Summary!$H$2:$H$99999,MATCH($C13,Postcode_Summary!$C$2:$C$99999,0)),"")) | I13: =IF($A13="","",IFERROR(INDEX(Shipping_Zones!$E$2:$E$5,MATCH($G13,Shipping_Zones!$A$2:$A$5,0)),"")) | J13: =IF($A13="","",IFERROR(INDEX(Shipping_Zones!$D$2:$D$5,MATCH($G13,Shipping_Zones!$A$2:$A$5,0)),"")) | K13: =IF($A13="","",IF(IFERROR(MATCH($C13,Postcode_Summary!$C$2:$C$99999,0),"ERR")="ERR","⚠ Check postcode/state",IF($H13=TRUE(),"PO Box flagged in source data",""))) | L13: =IF($A13="","",IFERROR(INDEX(Postcode_Summary!$T$2:$T$99999,MATCH($C13,Postcode_Summary!$C$2:$C$99999,0)),"")) | M13: =IF($A13="","",IFERROR(INDEX(Postcode_Summary!$X$2:$X$99999,MATCH($C13,Postcode_Summary!$C$2:$C$99999,0)),"")) | N13: =IF($A13="","",IFERROR(INDEX(Postcode_Summary!$Z$2:$Z$99999,MATCH($C13,Postcode_Summary!$C$2:$C$99999,0)),"")) | O13: =IF($A13="","",IFERROR(INDEX(Postcode_Summary!$V$2:$V$99999,MATCH($C13,Postcode_Summary!$C$2:$C$99999,0)),"")) | P13: =IF($A13="","",IFERROR(INDEX(Postcode_Summary!$AD$2:$AD$99999,MATCH($C13,Postcode_Summary!$C$2:$C$99999,0)),"")) | Q13: =IF($A13="","",IFERROR(INDEX(Postcode_Summary!$AE$2:$AE$99999,MATCH($C13,Postcode_Summary!$C$2:$C$99999,0)),"")) | R13: =IF($A13="","",IFERROR(INDEX(Postcode_Summary!$AB$2:$AB$99999,MATCH($C13,Postcode_Summary!$C$2:$C$99999,0)),""))
C14: =IF($A14="","",IFERROR(IF($B14<>"",$A14&"|"&$B14,$A14&"|"&INDEX(Postcode_Summary!$B$2:$B$99999,MATCH($A14,Postcode_Summary!$A$2:$A$99999,0))),"")) | D14: =IF($A14="","",IFERROR(INDEX(Postcode_Summary!$D$2:$D$99999,MATCH($C14,Postcode_Summary!$C$2:$C$99999,0)),IF($C14="","⚠ Postcode not recognised","⚠ State mismatch"))) | E14: =IF($A14="","",IFERROR(INDEX(Postcode_Summary!$Q$2:$Q$99999,MATCH($C14,Postcode_Summary!$C$2:$C$99999,0)),"")) | F14: =IF($A14="","",IFERROR(INDEX(Postcode_Summary!$R$2:$R$99999,MATCH($C14,Postcode_Summary!$C$2:$C$99999,0)),"")) | G14: =IF($A14="","",IFERROR(VLOOKUP($E14,Shipping_Zones!$A$7:$B$14,2,FALSE()),"")) | H14: =IF($A14="","",IFERROR(INDEX(Postcode_Summary!$H$2:$H$99999,MATCH($C14,Postcode_Summary!$C$2:$C$99999,0)),"")) | I14: =IF($A14="","",IFERROR(INDEX(Shipping_Zones!$E$2:$E$5,MATCH($G14,Shipping_Zones!$A$2:$A$5,0)),"")) | J14: =IF($A14="","",IFERROR(INDEX(Shipping_Zones!$D$2:$D$5,MATCH($G14,Shipping_Zones!$A$2:$A$5,0)),"")) | K14: =IF($A14="","",IF(IFERROR(MATCH($C14,Postcode_Summary!$C$2:$C$99999,0),"ERR")="ERR","⚠ Check postcode/state",IF($H14=TRUE(),"PO Box flagged in source data",""))) | L14: =IF($A14="","",IFERROR(INDEX(Postcode_Summary!$T$2:$T$99999,MATCH($C14,Postcode_Summary!$C$2:$C$99999,0)),"")) | M14: =IF($A14="","",IFERROR(INDEX(Postcode_Summary!$X$2:$X$99999,MATCH($C14,Postcode_Summary!$C$2:$C$99999,0)),"")) | N14: =IF($A14="","",IFERROR(INDEX(Postcode_Summary!$Z$2:$Z$99999,MATCH($C14,Postcode_Summary!$C$2:$C$99999,0)),"")) | O14: =IF($A14="","",IFERROR(INDEX(Postcode_Summary!$V$2:$V$99999,MATCH($C14,Postcode_Summary!$C$2:$C$99999,0)),"")) | P14: =IF($A14="","",IFERROR(INDEX(Postcode_Summary!$AD$2:$AD$99999,MATCH($C14,Postcode_Summary!$C$2:$C$99999,0)),"")) | Q14: =IF($A14="","",IFERROR(INDEX(Postcode_Summary!$AE$2:$AE$99999,MATCH($C14,Postcode_Summary!$C$2:$C$99999,0)),"")) | R14: =IF($A14="","",IFERROR(INDEX(Postcode_Summary!$AB$2:$AB$99999,MATCH($C14,Postcode_Summary!$C$2:$C$99999,0)),""))
C15: =IF($A15="","",IFERROR(IF($B15<>"",$A15&"|"&$B15,$A15&"|"&INDEX(Postcode_Summary!$B$2:$B$99999,MATCH($A15,Postcode_Summary!$A$2:$A$99999,0))),"")) | D15: =IF($A15="","",IFERROR(INDEX(Postcode_Summary!$D$2:$D$99999,MATCH($C15,Postcode_Summary!$C$2:$C$99999,0)),IF($C15="","⚠ Postcode not recognised","⚠ State mismatch"))) | E15: =IF($A15="","",IFERROR(INDEX(Postcode_Summary!$Q$2:$Q$99999,MATCH($C15,Postcode_Summary!$C$2:$C$99999,0)),"")) | F15: =IF($A15="","",IFERROR(INDEX(Postcode_Summary!$R$2:$R$99999,MATCH($C15,Postcode_Summary!$C$2:$C$99999,0)),"")) | G15: =IF($A15="","",IFERROR(VLOOKUP($E15,Shipping_Zones!$A$7:$B$14,2,FALSE()),"")) | H15: =IF($A15="","",IFERROR(INDEX(Postcode_Summary!$H$2:$H$99999,MATCH($C15,Postcode_Summary!$C$2:$C$99999,0)),"")) | I15: =IF($A15="","",IFERROR(INDEX(Shipping_Zones!$E$2:$E$5,MATCH($G15,Shipping_Zones!$A$2:$A$5,0)),"")) | J15: =IF($A15="","",IFERROR(INDEX(Shipping_Zones!$D$2:$D$5,MATCH($G15,Shipping_Zones!$A$2:$A$5,0)),"")) | K15: =IF($A15="","",IF(IFERROR(MATCH($C15,Postcode_Summary!$C$2:$C$99999,0),"ERR")="ERR","⚠ Check postcode/state",IF($H15=TRUE(),"PO Box flagged in source data",""))) | L15: =IF($A15="","",IFERROR(INDEX(Postcode_Summary!$T$2:$T$99999,MATCH($C15,Postcode_Summary!$C$2:$C$99999,0)),"")) | M15: =IF($A15="","",IFERROR(INDEX(Postcode_Summary!$X$2:$X$99999,MATCH($C15,Postcode_Summary!$C$2:$C$99999,0)),"")) | N15: =IF($A15="","",IFERROR(INDEX(Postcode_Summary!$Z$2:$Z$99999,MATCH($C15,Postcode_Summary!$C$2:$C$99999,0)),"")) | O15: =IF($A15="","",IFERROR(INDEX(Postcode_Summary!$V$2:$V$99999,MATCH($C15,Postcode_Summary!$C$2:$C$99999,0)),"")) | P15: =IF($A15="","",IFERROR(INDEX(Postcode_Summary!$AD$2:$AD$99999,MATCH($C15,Postcode_Summary!$C$2:$C$99999,0)),"")) | Q15: =IF($A15="","",IFERROR(INDEX(Postcode_Summary!$AE$2:$AE$99999,MATCH($C15,Postcode_Summary!$C$2:$C$99999,0)),"")) | R15: =IF($A15="","",IFERROR(INDEX(Postcode_Summary!$AB$2:$AB$99999,MATCH($C15,Postcode_Summary!$C$2:$C$99999,0)),""))
C16: =IF($A16="","",IFERROR(IF($B16<>"",$A16&"|"&$B16,$A16&"|"&INDEX(Postcode_Summary!$B$2:$B$99999,MATCH($A16,Postcode_Summary!$A$2:$A$99999,0))),"")) | D16: =IF($A16="","",IFERROR(INDEX(Postcode_Summary!$D$2:$D$99999,MATCH($C16,Postcode_Summary!$C$2:$C$99999,0)),IF($C16="","⚠ Postcode not recognised","⚠ State mismatch"))) | E16: =IF($A16="","",IFERROR(INDEX(Postcode_Summary!$Q$2:$Q$99999,MATCH($C16,Postcode_Summary!$C$2:$C$99999,0)),"")) | F16: =IF($A16="","",IFERROR(INDEX(Postcode_Summary!$R$2:$R$99999,MATCH($C16,Postcode_Summary!$C$2:$C$99999,0)),"")) | G16: =IF($A16="","",IFERROR(VLOOKUP($E16,Shipping_Zones!$A$7:$B$14,2,FALSE()),"")) | H16: =IF($A16="","",IFERROR(INDEX(Postcode_Summary!$H$2:$H$99999,MATCH($C16,Postcode_Summary!$C$2:$C$99999,0)),"")) | I16: =IF($A16="","",IFERROR(INDEX(Shipping_Zones!$E$2:$E$5,MATCH($G16,Shipping_Zones!$A$2:$A$5,0)),"")) | J16: =IF($A16="","",IFERROR(INDEX(Shipping_Zones!$D$2:$D$5,MATCH($G16,Shipping_Zones!$A$2:$A$5,0)),"")) | K16: =IF($A16="","",IF(IFERROR(MATCH($C16,Postcode_Summary!$C$2:$C$99999,0),"ERR")="ERR","⚠ Check postcode/state",IF($H16=TRUE(),"PO Box flagged in source data",""))) | L16: =IF($A16="","",IFERROR(INDEX(Postcode_Summary!$T$2:$T$99999,MATCH($C16,Postcode_Summary!$C$2:$C$99999,0)),"")) | M16: =IF($A16="","",IFERROR(INDEX(Postcode_Summary!$X$2:$X$99999,MATCH($C16,Postcode_Summary!$C$2:$C$99999,0)),"")) | N16: =IF($A16="","",IFERROR(INDEX(Postcode_Summary!$Z$2:$Z$99999,MATCH($C16,Postcode_Summary!$C$2:$C$99999,0)),"")) | O16: =IF($A16="","",IFERROR(INDEX(Postcode_Summary!$V$2:$V$99999,MATCH($C16,Postcode_Summary!$C$2:$C$99999,0)),"")) | P16: =IF($A16="","",IFERROR(INDEX(Postcode_Summary!$AD$2:$AD$99999,MATCH($C16,Postcode_Summary!$C$2:$C$99999,0)),"")) | Q16: =IF($A16="","",IFERROR(INDEX(Postcode_Summary!$AE$2:$AE$99999,MATCH($C16,Postcode_Summary!$C$2:$C$99999,0)),"")) | R16: =IF($A16="","",IFERROR(INDEX(Postcode_Summary!$AB$2:$AB$99999,MATCH($C16,Postcode_Summary!$C$2:$C$99999,0)),""))
C17: =IF($A17="","",IFERROR(IF($B17<>"",$A17&"|"&$B17,$A17&"|"&INDEX(Postcode_Summary!$B$2:$B$99999,MATCH($A17,Postcode_Summary!$A$2:$A$99999,0))),"")) | D17: =IF($A17="","",IFERROR(INDEX(Postcode_Summary!$D$2:$D$99999,MATCH($C17,Postcode_Summary!$C$2:$C$99999,0)),IF($C17="","⚠ Postcode not recognised","⚠ State mismatch"))) | E17: =IF($A17="","",IFERROR(INDEX(Postcode_Summary!$Q$2:$Q$99999,MATCH($C17,Postcode_Summary!$C$2:$C$99999,0)),"")) | F17: =IF($A17="","",IFERROR(INDEX(Postcode_Summary!$R$2:$R$99999,MATCH($C17,Postcode_Summary!$C$2:$C$99999,0)),"")) | G17: =IF($A17="","",IFERROR(VLOOKUP($E17,Shipping_Zones!$A$7:$B$14,2,FALSE()),"")) | H17: =IF($A17="","",IFERROR(INDEX(Postcode_Summary!$H$2:$H$99999,MATCH($C17,Postcode_Summary!$C$2:$C$99999,0)),"")) | I17: =IF($A17="","",IFERROR(INDEX(Shipping_Zones!$E$2:$E$5,MATCH($G17,Shipping_Zones!$A$2:$A$5,0)),"")) | J17: =IF($A17="","",IFERROR(INDEX(Shipping_Zones!$D$2:$D$5,MATCH($G17,Shipping_Zones!$A$2:$A$5,0)),"")) | K17: =IF($A17="","",IF(IFERROR(MATCH($C17,Postcode_Summary!$C$2:$C$99999,0),"ERR")="ERR","⚠ Check postcode/state",IF($H17=TRUE(),"PO Box flagged in source data",""))) | L17: =IF($A17="","",IFERROR(INDEX(Postcode_Summary!$T$2:$T$99999,MATCH($C17,Postcode_Summary!$C$2:$C$99999,0)),"")) | M17: =IF($A17="","",IFERROR(INDEX(Postcode_Summary!$X$2:$X$99999,MATCH($C17,Postcode_Summary!$C$2:$C$99999,0)),"")) | N17: =IF($A17="","",IFERROR(INDEX(Postcode_Summary!$Z$2:$Z$99999,MATCH($C17,Postcode_Summary!$C$2:$C$99999,0)),"")) | O17: =IF($A17="","",IFERROR(INDEX(Postcode_Summary!$V$2:$V$99999,MATCH($C17,Postcode_Summary!$C$2:$C$99999,0)),"")) | P17: =IF($A17="","",IFERROR(INDEX(Postcode_Summary!$AD$2:$AD$99999,MATCH($C17,Postcode_Summary!$C$2:$C$99999,0)),"")) | Q17: =IF($A17="","",IFERROR(INDEX(Postcode_Summary!$AE$2:$AE$99999,MATCH($C17,Postcode_Summary!$C$2:$C$99999,0)),"")) | R17: =IF($A17="","",IFERROR(INDEX(Postcode_Summary!$AB$2:$AB$99999,MATCH($C17,Postcode_Summary!$C$2:$C$99999,0)),""))
C18: =IF($A18="","",IFERROR(IF($B18<>"",$A18&"|"&$B18,$A18&"|"&INDEX(Postcode_Summary!$B$2:$B$99999,MATCH($A18,Postcode_Summary!$A$2:$A$99999,0))),"")) | D18: =IF($A18="","",IFERROR(INDEX(Postcode_Summary!$D$2:$D$99999,MATCH($C18,Postcode_Summary!$C$2:$C$99999,0)),IF($C18="","⚠ Postcode not recognised","⚠ State mismatch"))) | E18: =IF($A18="","",IFERROR(INDEX(Postcode_Summary!$Q$2:$Q$99999,MATCH($C18,Postcode_Summary!$C$2:$C$99999,0)),"")) | F18: =IF($A18="","",IFERROR(INDEX(Postcode_Summary!$R$2:$R$99999,MATCH($C18,Postcode_Summary!$C$2:$C$99999,0)),"")) | G18: =IF($A18="","",IFERROR(VLOOKUP($E18,Shipping_Zones!$A$7:$B$14,2,FALSE()),"")) | H18: =IF($A18="","",IFERROR(INDEX(Postcode_Summary!$H$2:$H$99999,MATCH($C18,Postcode_Summary!$C$2:$C$99999,0)),"")) | I18: =IF($A18="","",IFERROR(INDEX(Shipping_Zones!$E$2:$E$5,MATCH($G18,Shipping_Zones!$A$2:$A$5,0)),"")) | J18: =IF($A18="","",IFERROR(INDEX(Shipping_Zones!$D$2:$D$5,MATCH($G18,Shipping_Zones!$A$2:$A$5,0)),"")) | K18: =IF($A18="","",IF(IFERROR(MATCH($C18,Postcode_Summary!$C$2:$C$99999,0),"ERR")="ERR","⚠ Check postcode/state",IF($H18=TRUE(),"PO Box flagged in source data",""))) | L18: =IF($A18="","",IFERROR(INDEX(Postcode_Summary!$T$2:$T$99999,MATCH($C18,Postcode_Summary!$C$2:$C$99999,0)),"")) | M18: =IF($A18="","",IFERROR(INDEX(Postcode_Summary!$X$2:$X$99999,MATCH($C18,Postcode_Summary!$C$2:$C$99999,0)),"")) | N18: =IF($A18="","",IFERROR(INDEX(Postcode_Summary!$Z$2:$Z$99999,MATCH($C18,Postcode_Summary!$C$2:$C$99999,0)),"")) | O18: =IF($A18="","",IFERROR(INDEX(Postcode_Summary!$V$2:$V$99999,MATCH($C18,Postcode_Summary!$C$2:$C$99999,0)),"")) | P18: =IF($A18="","",IFERROR(INDEX(Postcode_Summary!$AD$2:$AD$99999,MATCH($C18,Postcode_Summary!$C$2:$C$99999,0)),"")) | Q18: =IF($A18="","",IFERROR(INDEX(Postcode_Summary!$AE$2:$AE$99999,MATCH($C18,Postcode_Summary!$C$2:$C$99999,0)),"")) | R18: =IF($A18="","",IFERROR(INDEX(Postcode_Summary!$AB$2:$AB$99999,MATCH($C18,Postcode_Summary!$C$2:$C$99999,0)),""))
C19: =IF($A19="","",IFERROR(IF($B19<>"",$A19&"|"&$B19,$A19&"|"&INDEX(Postcode_Summary!$B$2:$B$99999,MATCH($A19,Postcode_Summary!$A$2:$A$99999,0))),"")) | D19: =IF($A19="","",IFERROR(INDEX(Postcode_Summary!$D$2:$D$99999,MATCH($C19,Postcode_Summary!$C$2:$C$99999,0)),IF($C19="","⚠ Postcode not recognised","⚠ State mismatch"))) | E19: =IF($A19="","",IFERROR(INDEX(Postcode_Summary!$Q$2:$Q$99999,MATCH($C19,Postcode_Summary!$C$2:$C$99999,0)),"")) | F19: =IF($A19="","",IFERROR(INDEX(Postcode_Summary!$R$2:$R$99999,MATCH($C19,Postcode_Summary!$C$2:$C$99999,0)),"")) | G19: =IF($A19="","",IFERROR(VLOOKUP($E19,Shipping_Zones!$A$7:$B$14,2,FALSE()),"")) | H19: =IF($A19="","",IFERROR(INDEX(Postcode_Summary!$H$2:$H$99999,MATCH($C19,Postcode_Summary!$C$2:$C$99999,0)),"")) | I19: =IF($A19="","",IFERROR(INDEX(Shipping_Zones!$E$2:$E$5,MATCH($G19,Shipping_Zones!$A$2:$A$5,0)),"")) | J19: =IF($A19="","",IFERROR(INDEX(Shipping_Zones!$D$2:$D$5,MATCH($G19,Shipping_Zones!$A$2:$A$5,0)),"")) | K19: =IF($A19="","",IF(IFERROR(MATCH($C19,Postcode_Summary!$C$2:$C$99999,0),"ERR")="ERR","⚠ Check postcode/state",IF($H19=TRUE(),"PO Box flagged in source data",""))) | L19: =IF($A19="","",IFERROR(INDEX(Postcode_Summary!$T$2:$T$99999,MATCH($C19,Postcode_Summary!$C$2:$C$99999,0)),"")) | M19: =IF($A19="","",IFERROR(INDEX(Postcode_Summary!$X$2:$X$99999,MATCH($C19,Postcode_Summary!$C$2:$C$99999,0)),"")) | N19: =IF($A19="","",IFERROR(INDEX(Postcode_Summary!$Z$2:$Z$99999,MATCH($C19,Postcode_Summary!$C$2:$C$99999,0)),"")) | O19: =IF($A19="","",IFERROR(INDEX(Postcode_Summary!$V$2:$V$99999,MATCH($C19,Postcode_Summary!$C$2:$C$99999,0)),"")) | P19: =IF($A19="","",IFERROR(INDEX(Postcode_Summary!$AD$2:$AD$99999,MATCH($C19,Postcode_Summary!$C$2:$C$99999,0)),"")) | Q19: =IF($A19="","",IFERROR(INDEX(Postcode_Summary!$AE$2:$AE$99999,MATCH($C19,Postcode_Summary!$C$2:$C$99999,0)),"")) | R19: =IF($A19="","",IFERROR(INDEX(Postcode_Summary!$AB$2:$AB$99999,MATCH($C19,Postcode_Summary!$C$2:$C$99999,0)),""))
... C1007: =IF($A1007="","",IFERROR(IF($B1007<>"",$A1007&"|"&$B1007,$A1007&"|"&INDEX(Postcode_Summary!$B$2:$B$99999,MATCH($A1007,Postcode_Summary!$A$2:$A$99999,0))),"")) | D1007: =IF($A1007="","",IFERROR(INDEX(Postcode_Summary!$D$2:$D$99999,MATCH($C1007,Postcode_Summary!$C$2:$C$99999,0)),IF($C1007="","⚠ Postcode not recognised","⚠ State mismatch"))) | E1007: =IF($A1007="","",IFERROR(INDEX(Postcode_Summary!$Q$2:$Q$99999,MATCH($C1007,Postcode_Summary!$C$2:$C$99999,0)),"")) | F1007: =IF($A1007="","",IFERROR(INDEX(Postcode_Summary!$R$2:$R$99999,MATCH($C1007,Postcode_Summary!$C$2:$C$99999,0)),"")) | G1007: =IF($A1007="","",IFERROR(VLOOKUP($E1007,Shipping_Zones!$A$7:$B$14,2,FALSE()),"")) | H1007: =IF($A1007="","",IFERROR(INDEX(Postcode_Summary!$H$2:$H$99999,MATCH($C1007,Postcode_Summary!$C$2:$C$99999,0)),"")) | I1007: =IF($A1007="","",IFERROR(INDEX(Shipping_Zones!$E$2:$E$5,MATCH($G1007,Shipping_Zones!$A$2:$A$5,0)),"")) | J1007: =IF($A1007="","",IFERROR(INDEX(Shipping_Zones!$D$2:$D$5,MATCH($G1007,Shipping_Zones!$A$2:$A$5,0)),"")) | K1007: =IF($A1007="","",IF(IFERROR(MATCH($C1007,Postcode_Summary!$C$2:$C$99999,0),"ERR")="ERR","⚠ Check postcode/state",IF($H1007=TRUE(),"PO Box flagged in source data",""))) | L1007: =IF($A1007="","",IFERROR(INDEX(Postcode_Summary!$T$2:$T$99999,MATCH($C1007,Postcode_Summary!$C$2:$C$99999,0)),"")) | M1007: =IF($A1007="","",IFERROR(INDEX(Postcode_Summary!$X$2:$X$99999,MATCH($C1007,Postcode_Summary!$C$2:$C$99999,0)),"")) | N1007: =IF($A1007="","",IFERROR(INDEX(Postcode_Summary!$Z$2:$Z$99999,MATCH($C1007,Postcode_Summary!$C$2:$C$99999,0)),"")) | O1007: =IF($A1007="","",IFERROR(INDEX(Postcode_Summary!$V$2:$V$99999,MATCH($C1007,Postcode_Summary!$C$2:$C$99999,0)),"")) | P1007: =IF($A1007="","",IFERROR(INDEX(Postcode_Summary!$AD$2:$AD$99999,MATCH($C1007,Postcode_Summary!$C$2:$C$99999,0)),"")) | Q1007: =IF($A1007="","",IFERROR(INDEX(Postcode_Summary!$AE$2:$AE$99999,MATCH($C1007,Postcode_Summary!$C$2:$C$99999,0)),"")) | R1007: =IF($A1007="","",IFERROR(INDEX(Postcode_Summary!$AB$2:$AB$99999,MATCH($C1007,Postcode_Summary!$C$2:$C$99999,0)),""))

Sheet Shopify_Zones
A1: Shopify Shipping Zone Postcodes
A2: Copy-paste these comma-separated lists directly into Shopify shipping zone postcode fields.
A3: Generated from Shipping_MMM classifications. Last updated: 18 Feb 2026.
A5: Zone 1: Metro (MMM1)
A6: Free shipping eligible. Use for Shopify "Rest of Australia" exclusion or metro-only free shipping rules.
A7: Postcode count: 1167
A8: 200,1100,1215,1220,1225,1230,1231,1235,1239,1240,1291,1300,1335,1340,1350,1355,1360,1405,1435,1445,1450,1455,1460,1465,1466,1470,1475,1480,1481,1485,1490,1495,1499,1515,1560,1565,1570,1585,1590,1595,1630,1635,1640,1655,1660,1670,1675,1680,1685,1700,1710,1715,1730,1750,1755,1765,1790,1800,1805,1825,1835,1851,1860,1871,1874,1875,1885,1890,2000,2001,2002,2004,2006,2007,2008,2009,2010,2011,2012,2015,2016,2017,2018,2019,2020,2021,2022,2023,2024,2025,2026,2027,2028,2029,2030,2031,2032,2033,2034,2035,2036,2037,2038,2039,2040,2041,2042,2043,2044,2045,2046,2047,2048,2049,2050,2052,2055,2057,2059,2060,2061,2062,2063,2064,2065,2066,2067,2068,2069,2070,2071,2072,2073,2074,2075,2076,2077,2079,2080,2084,2085,2086,2087,2088,2089,2090,2091,2092,2093,2094,2095,2096,2097,2099,2100,2101,2102,2103,2104,2105,2106,2107,2108,2109,2110,2111,2112,2113,2114,2115,2116,2117,2118,2119,2120,2121,2122,2123,2124,2125,2126,2127,2128,2129,2130,2131,2132,2133,2134,2135,2136,2137,2138,2139,2140,2141,2142,2143,2144,2145,2146,2147,2148,2150,2151,2152,2153,2154,2155,2156,2158,2160,2161,2162,2163,2164,2165,2166,2167,2168,2170,2171,2172,2174,2175,2176,2177,2178,2179,2190,2191,2192,2193,2194,2195,2196,2197,2198,2199,2200,2203,2204,2205,2206,2207,2208,2209,2210,2211,2212,2213,2214,2216,2217,2218,2219,2220,2221,2222,2223,2224,2225,2226,2227,2228,2229,2230,2231,2234,2251,2252,2257,2260,2261,2262,2263,2264,2267,2278,2280,2282,2283,2284,2285,2286,2287,2289,2290,2291,2292,2293,2294,2295,2296,2297,2298,2299,2300,2302,2303,2304,2305,2306,2307,2308,2309,2310,2322,2327,2485,2486,2487,2488,2489,2490,2500,2502,2505,2506,2515,2516,2517,2518,2519,2520,2522,2525,2528,2529,2530,2556,2557,2558,2559,2563,2564,2565,2566,2567,2568,2600,2601,2602,2603,2604,2605,2606,2607,2608,2609,2610,2612,2614,2615,2616,2617,2619,2747,2748,2749,2750,2751,2753,2754,2759,2760,2761,2762,2763,2765,2766,2767,2768,2769,2770,2773,2774,2776,2777,2778,2779,2780,2782,2783,2784,2890,2891,2901,2902,2903,2904,2905,2906,2911,2912,2913,2914,3000,3001,3002,3003,3004,3006,3008,3010,3011,3012,3013,3015,3016,3018,3019,3020,3021,3022,3023,3024,3025,3026,3027,3028,3029,3031,3032,3033,3034,3036,3037,3038,3039,3040,3041,3042,3043,3044,3045,3046,3047,3048,3049,3050,3051,3052,3053,3054,3055,3056,3057,3058,3059,3060,3061,3062,3063,3064,3065,3066,3067,3068,3070,3071,3072,3073,3074,3075,3076,3078,3079,3081,3082,3083,3084,3085,3086,3087,3088,3089,3090,3091,3093,3094,3095,3096,3097,3101,3102,3103,3104,3105,3106,3107,3108,3109,3111,3113,3114,3115,3116,3121,3122,3123,3124,3125,3126,3127,3128,3129,3130,3131,3132,3133,3134,3135,3136,3137,3138,3140,3141,3142,3143,3144,3145,3146,3147,3148,3149,3150,3151,3152,3153,3154,3155,3156,3158,3159,3160,3161,3162,3163,3164,3165,3166,3167,3168,3169,3170,3171,3172,3173,3174,3175,3176,3177,3178,3179,3180,3181,3182,3183,3184,3185,3186,3187,3188,3189,3190,3191,3192,3193,3194,3195,3196,3197,3198,3199,3200,3201,3202,3204,3205,3206,3207,3214,3215,3216,3219,3220,3224,3335,3336,3337,3427,3428,3429,3750,3751,3752,3754,3755,3759,3765,3766,3767,3781,3782,3785,3786,3787,3788,3789,3791,3792,3793,3795,3796,3800,3802,3803,3804,3805,3806,3807,3808,3910,3911,3912,3913,3915,3918,3919,3920,3926,3927,3930,3931,3933,3934,3936,3938,3940,3941,3942,3943,3944,3975,3976,3977,3978,4000,4001,4002,4003,4004,4005,4006,4007,4008,4009,4010,4011,4012,4013,4014,4017,4018,4019,4020,4021,4022,4029,4030,4031,4032,4034,4035,4036,4037,4051,4053,4054,4055,4059,4060,4061,4064,4065,4066,4067,4068,4069,4070,4072,4073,4074,4075,4076,4077,4078,4101,4102,4103,4104,4105,4106,4107,4108,4109,4110,4111,4112,4113,4114,4115,4116,4117,4118,4119,4120,4121,4122,4123,4124,4125,4127,4128,4129,4130,4131,4132,4133,4151,4152,4153,4154,4155,4156,4157,4158,4159,4160,4161,4163,4164,4165,4169,4170,4171,4172,4173,4174,4178,4179,4205,4207,4208,4209,4210,4212,4213,4214,4215,4216,4217,4218,4219,4220,4221,4222,4224,4225,4226,4227,4230,4271,4272,4300,4301,4303,4304,4305,4500,4501,4502,4503,4504,4505,4506,4508,4509,4510,4511,4512,4513,4516,4551,4556,4557,4558,4559,4564,4566,4567,4572,4573,4575,5000,5001,5005,5006,5007,5008,5009,5010,5011,5012,5013,5014,5015,5016,5017,5018,5019,5020,5021,5022,5023,5024,5025,5031,5032,5033,5034,5035,5037,5038,5039,5040,5041,5042,5043,5044,5045,5046,5047,5048,5049,5050,5051,5052,5061,5062,5063,5064,5065,5066,5067,5068,5069,5070,5071,5072,5073,5074,5075,5076,5081,5082,5083,5084,5085,5086,5087,5088,5089,5090,5091,5092,5093,5094,5095,5096,5097,5098,5106,5107,5108,5109,5110,5111,5112,5113,5115,5116,5117,5118,5121,5125,5126,5127,5136,5137,5140,5141,5142,5150,5151,5152,5154,5155,5156,5158,5159,5160,5161,5162,5163,5164,5165,5166,5167,5168,5169,5170,5171,5173,5174,5800,5801,5810,5839,5942,5950,6000,6001,6003,6004,6005,6006,6007,6008,6009,6010,6011,6012,6014,6015,6016,6017,6018,6019,6020,6021,6022,6023,6024,6025,6026,6027,6028,6029,6030,6031,6032,6033,6034,6036,6038,6050,6051,6052,6053,6054,6055,6056,6057,6058,6059,6060,6061,6062,6063,6064,6065,6066,6067,6068,6069,6070,6071,6072,6073,6077,6079,6081,6090,6100,6101,6102,6103,6104,6105,6106,6107,6108,6109,6110,6112,6121,6123,6147,6148,6149,6150,6151,6152,6153,6154,6155,6156,6157,6158,6159,6160,6162,6163,6164,6165,6166,6167,6168,6169,6170,6171,6172,6173,6174,6175,6176,6180,6181,6182,6209,6210,6800,6809,6827,6830,6831,6837,6838,6839,6840,6841,6842,6843,6844,6845,6846,6847,6848,6849,6850,6865,6872,6892,6900,6901,6902,6903,6904,6905,6906,6907,6909,6910,6911,6912,6913,6914,6915,6916,6917,6918,6919,6920,6921,6922,6923,6924,6925,6926,6929,6931,6932,6933,6934,6935,6936,6939,6941,6942,6943,6944,6946,6947,6951,6952,6953,6954,6955,6956,6957,6958,6959,6960,6961,6963,6964,6965,6966,6967,6968,6969,6970,6979,6981,6982,6983,6984,6985,6986,6987,6988,6989,6990,6991,6992,6997,8001,8002,8003,8004,8006,8007,8008,8009,8010,8011,8012,8045,8051,8066,8069,8070,8071,8102,8107,8111,8120,8205,8383,8438,8511,8785,9464,9726,9999
A10: Zone 2: Regional (MMM2–3)
A11: Regional centres and large rural towns. Standard shipping rates.
A12: Postcode count: 303
A13: 800,801,803,804,810,811,812,813,814,815,820,821,828,829,832,834,835,836,839,906,907,909,2081,2082,2083,2157,2173,2232,2233,2256,2258,2265,2281,2318,2320,2323,2326,2334,2426,2430,2452,2477,2478,2508,2526,2527,2533,2541,2555,2560,2569,2570,2571,2574,2576,2618,2641,2651,2661,2678,2717,2739,2745,2752,2757,2785,2900,3030,3099,3139,3211,3212,3213,3217,3222,3223,3225,3226,3227,3228,3275,3278,3280,3281,3282,3331,3334,3338,3340,3350,3352,3353,3354,3355,3356,3357,3358,3363,3400,3430,3432,3453,3498,3500,3515,3550,3551,3552,3554,3555,3556,3557,3564,3614,3622,3629,3631,3632,3633,3634,3677,3688,3689,3690,3746,3753,3757,3758,3760,3761,3762,3770,3775,3809,3810,3812,3813,3814,3824,3840,3841,3842,3844,3854,3916,3928,3929,3937,3939,3980,3981,4223,4228,4270,4280,4306,4344,4345,4346,4350,4400,4507,4517,4518,4519,4520,4550,4553,4554,4555,4560,4561,4562,4563,4568,4655,4659,4662,4670,4700,4710,4711,4740,4750,4751,4811,4812,4813,4814,4865,4868,4869,4878,4879,5114,5120,5131,5132,5133,5134,5138,5139,5144,5153,5157,5172,5202,5211,5212,5213,5231,5232,5233,5240,5242,5243,5245,5250,5251,5252,5290,5350,5371,5400,5600,5608,5609,6035,6037,6074,6076,6078,6083,6111,6122,6125,6208,6211,6214,6223,6224,6226,6227,6228,6229,6230,6231,6232,6233,6237,6271,6280,6281,6432,6433,6530,6531,6556,6558,7000,7001,7002,7004,7005,7006,7007,7008,7009,7010,7011,7012,7015,7016,7017,7018,7019,7020,7021,7024,7025,7050,7051,7052,7053,7054,7055,7155,7170,7171,7173,7248,7249,7250,7267,7268,7277,7290,7291,7292,7300,7301,7320,7322
A15: Zone 3: Rural (MMM4–5)
... A38: 200,801,803,804,811,813,814,815,821,831,851,861,871,881,906,907,909,1100,1215,1220,1225,1230,1231,1235,1239,1240,1291,1300,1335,1340,1350,1355,1360,1405,1435,1445,1450,1455,1460,1465,1466,1470,1475,1480,1481,1485,1490,1495,1499,1515,1560,1565,1570,1585,1590,1595,1630,1635,1640,1655,1660,1670,1675,1680,1685,1700,1710,1715,1730,1750,1755,1765,1790,1800,1805,1825,1835,1851,1860,1871,1874,1875,1885,1890,2001,2002,2004,2006,2012,2052,2055,2057,2059,2091,2109,2123,2124,2129,2139,2252,2309,2310,2331,2348,2351,2442,2520,2522,2608,2610,2616,2708,2751,2891,2901,3001,3050,3086,3164,3176,3353,3354,3402,3502,3552,3554,3619,3632,3643,3661,3671,3676,3689,3694,3724,3736,3800,3841,3853,4001,4002,4003,4004,4029,4072,4219,4222,4230,4271,4345,4803,4813,5001,5005,5071,5800,5801,5810,5839,5942,6001,6231,6331,6332,6433,6531,6731,6799,6800,6809,6827,6830,6831,6837,6838,6839,6840,6841,6842,6843,6844,6845,6846,6847,6848,6849,6850,6865,6872,6892,6900,6901,6902,6903,6904,6905,6906,6907,6909,6910,6911,6912,6913,6914,6915,6916,6917,6918,6919,6920,6921,6922,6923,6924,6925,6926,6929,6931,6932,6933,6934,6935,6936,6939,6941,6942,6943,6944,6946,6947,6951,6952,6953,6954,6955,6956,6957,6958,6959,6960,6961,6963,6964,6965,6966,6967,6968,6969,6970,6979,6981,6982,6983,6984,6985,6986,6987,6988,6989,6990,6991,6992,6997,7001,7002,7006,7051,8001,8002,8003,8004,8006,8007,8008,8009,8010,8011,8012,8045,8051,8066,8069,8070,8071,8102,8107,8111,8120,8205,8383,8438,8511,8785,9464,9726

Sheet Postcode_Summary
A1: Postcode | B1: State | C1: PC_State_Key | D1: RepresentativePlace | E1: PlaceSample_5 | F1: PlaceCount | G1: UniquePlaces | H1: Any_POBox | I1: DeliveryType | J1: Qualifier | K1: MMM_2023_Primary | L1: MMM_2023_PrimaryLabel | M1: MMM_2023_PrimaryShare | N1: MMM_2023_Breakdown | O1: MMM_2023_PrimaryArea_km2 | P1: POA_Area_km2 | Q1: Shipping_MMM | R1: Shipping_MMMLabel | S1: Shipping_MMM_Source | T1: NSW_LHD | U1: NSW_LHD_Code | V1: ERP_2021 | W1: Indigenous_Pop | X1: Indigenous_Pct | Y1: IRSD_Score | Z1: IRSD_Decile | AA1: RA_Approx | AB1: RA_Label | AC1: RA_Source | AD1: PHN_Code | AE1: PHN_Name | AF1: PHN_Ratio | AG1: PHN_Split_Note
A2: 200 | B2: ACT | C2: 200|ACT | D2: Australian National University | E2: Australian National University | F2: 1 | G2: 1 | H2: =TRUE() | I2: Post Office Boxes | J2: PO BOXES | Q2: 1 | R2: MMM1 - Metropolitan area | S2: Metro PO Box/LVR (no POA; assigned from metro postcode range) | T2: Sydney LHD | U2: X700 | AA2: 1 | AB2: RA1 - Major cities of Australia | AC2: Approximate: derived from Shipping_MMM via standard MMM→RA mapping | AD2: PHN801 | AE2: Australian Capital Territory | AG2: Inferred (Single-state PHN)
A3: 800 | B3: NT | C3: 800|NT | D3: Darwin City | E3: Darwin City | F3: 1 | G3: 1 | H3: =FALSE() | K3: 2 | L3: MMM2 - Regional centre | M3: 1 | N3: 2:100.0% | O3: 3.1738 | P3: 3.1731 | Q3: 2 | R3: MMM2 - Regional centre | S3: MMM 2023 (POA concordance) | V3: 7149 | W3: 249 | X3: 3.5 | Y3: 1064.3 | Z3: 9 | AA3: 2 | AB3: RA2 - Inner regional Australia | AC3: Approximate: derived from Shipping_MMM via standard MMM→RA mapping (MMM2-3 both map to RA2) | AD3: PHN701 | AE3: Northern Territory | AF3: 1
A4: 801 | B4: NT | C4: 801|NT | D4: Darwin | E4: Darwin | F4: 1 | G4: 1 | H4: =TRUE() | I4: Post Office Boxes | J4: GPO BOXES & BAGS | Q4: 2 | R4: MMM2 - Regional centre | S4: No POA; assigned from nearest classified postcode | AA4: 2 | AB4: RA2 - Inner regional Australia | AC4: Approximate: derived from Shipping_MMM via standard MMM→RA mapping (MMM2-3 both map to RA2) | AD4: PHN701 | AE4: Northern Territory | AG4: Inferred (Single-state PHN)
A5: 803 | B5: NT | C5: 803|NT | D5: Wagait Beach | E5: Wagait Beach | F5: 1 | G5: 1 | H5: =TRUE() | I5: Post Office Boxes | J5: PO BOXES | Q5: 2 | R5: MMM2 - Regional centre | S5: No POA; assigned from nearest classified postcode | AA5: 2 | AB5: RA2 - Inner regional Australia | AC5: Approximate: derived from Shipping_MMM via standard MMM→RA mapping (MMM2-3 both map to RA2) | AD5: PHN701 | AE5: Northern Territory | AG5: Inferred (Single-state PHN)
A6: 804 | B6: NT | C6: 804|NT | D6: Parap | E6: Parap | F6: 1 | G6: 1 | H6: =TRUE() | I6: Post Office Boxes | J6: PO BOXES | Q6: 2 | R6: MMM2 - Regional centre | S6: No POA; assigned from nearest classified postcode | AA6: 2 | AB6: RA2 - Inner regional Australia | AC6: Approximate: derived from Shipping_MMM via standard MMM→RA mapping (MMM2-3 both map to RA2) | AD6: PHN701 | AE6: Northern Territory | AG6: Inferred (Single-state PHN)
A7: 810 | B7: NT | C7: 810|NT | D7: Alawa | E7: Alawa, Brinkin, Casuarina, Coconut Grove, Jingili | F7: 16 | G7: 16 | H7: =FALSE() | K7: 2 | L7: MMM2 - Regional centre | M7: 1 | N7: 2:100.0% | O7: 24.4286 | P7: 24.4283 | Q7: 2 | R7: MMM2 - Regional centre | S7: MMM 2023 (POA concordance) | V7: 34330 | W7: 2623 | X7: 7.6 | Y7: 1026.8 | Z7: 7 | AA7: 2 | AB7: RA2 - Inner regional Australia | AC7: Approximate: derived from Shipping_MMM via standard MMM→RA mapping (MMM2-3 both map to RA2) | AD7: PHN701 | AE7: Northern Territory | AF7: 1
A8: 811 | B8: NT | C8: 811|NT | D8: Casuarina | E8: Casuarina | F8: 1 | G8: 1 | H8: =TRUE() | I8: Post Office Boxes | J8: PO BOXES | Q8: 2 | R8: MMM2 - Regional centre | S8: No POA; assigned from nearest classified postcode | AA8: 2 | AB8: RA2 - Inner regional Australia | AC8: Approximate: derived from Shipping_MMM via standard MMM→RA mapping (MMM2-3 both map to RA2) | AD8: PHN701 | AE8: Northern Territory | AG8: Inferred (Single-state PHN)
A9: 812 | B9: NT | C9: 812|NT | D9: Anula | E9: Anula, Buffalo Creek, Holmes, Karama, Leanyer | F9: 8 | G9: 8 | H9: =FALSE() | K9: 2 | L9: MMM2 - Regional centre | M9: 1 | N9: 2:100.0% | O9: 35.8897 | P9: 35.8899 | Q9: 2 | R9: MMM2 - Regional centre | S9: MMM 2023 (POA concordance) | V9: 18634 | W9: 2778 | X9: 14.9 | Y9: 981.1 | Z9: 4 | AA9: 2 | AB9: RA2 - Inner regional Australia | AC9: Approximate: derived from Shipping_MMM via standard MMM→RA mapping (MMM2-3 both map to RA2) | AD9: PHN701 | AE9: Northern Territory | AF9: 1
A10: 813 | B10: NT | C10: 813|NT | D10: Karama | E10: Karama | F10: 1 | G10: 1 | H10: =TRUE() | I10: Post Office Boxes | J10: PO BOXES | Q10: 2 | R10: MMM2 - Regional centre | S10: No POA; assigned from nearest classified postcode | AA10: 2 | AB10: RA2 - Inner regional Australia | AC10: Approximate: derived from Shipping_MMM via standard MMM→RA mapping (MMM2-3 both map to RA2) | AD10: PHN701 | AE10: Northern Territory | AG10: Inferred (Single-state PHN)
A11: 814 | B11: NT | C11: 814|NT | D11: Nightcliff | E11: Nightcliff | F11: 1 | G11: 1 | H11: =TRUE() | I11: Post Office Boxes | J11: PO BOXES | Q11: 2 | R11: MMM2 - Regional centre | S11: No POA; assigned from nearest classified postcode | AA11: 2 | AB11: RA2 - Inner regional Australia | AC11: Approximate: derived from Shipping_MMM via standard MMM→RA mapping (MMM2-3 both map to RA2) | AD11: PHN701 | AE11: Northern Territory | AG11: Inferred (Single-state PHN)
A12: 815 | B12: NT | C12: 815|NT | D12: Charles Darwin University | E12: Charles Darwin University | F12: 1 | G12: 1 | H12: =TRUE() | I12: Post Office Boxes | J12: PO BOXES | Q12: 2 | R12: MMM2 - Regional centre | S12: No POA; assigned from nearest classified postcode | AA12: 2 | AB12: RA2 - Inner regional Australia | AC12: Approximate: derived from Shipping_MMM via standard MMM→RA mapping (MMM2-3 both map to RA2) | AD12: PHN701 | AE12: Northern Territory | AG12: Inferred (Single-state PHN)
A13: 820 | B13: NT | C13: 820|NT | D13: Bayview | E13: Bayview, Charles Darwin, Coonawarra, Darwin Dc, East Point | F13: 15 | G13: 15 | H13: =FALSE() | K13: 2 | L13: MMM2 - Regional centre | M13: 1 | N13: 2:100.0% | O13: 39.064 | P13: 39.0642 | Q13: 2 | R13: MMM2 - Regional centre | S13: MMM 2023 (POA concordance) | V13: 19920 | W13: 1191 | X13: 6 | Y13: 1061.3 | Z13: 9 | AA13: 2 | AB13: RA2 - Inner regional Australia | AC13: Approximate: derived from Shipping_MMM via standard MMM→RA mapping (MMM2-3 both map to RA2) | AD13: PHN701 | AE13: Northern Territory | AF13: 1
A14: 821 | B14: NT | C14: 821|NT | D14: Winnellie | E14: Winnellie | F14: 1 | G14: 1 | H14: =TRUE() | I14: Post Office Boxes | J14: PO BOXES | Q14: 2 | R14: MMM2 - Regional centre | S14: No POA; assigned from nearest classified postcode | AA14: 2 | AB14: RA2 - Inner regional Australia | AC14: Approximate: derived from Shipping_MMM via standard MMM→RA mapping (MMM2-3 both map to RA2) | AD14: PHN701 | AE14: Northern Territory | AG14: Inferred (Single-state PHN)
A15: 822 | B15: NT | C15: 822|NT | D15: Acacia Hills | E15: Acacia Hills, Angurugu, Anindilyakwa, Bathurst Island, Bees Creek | F15: 97 | G15: 97 | H15: =FALSE() | J15: PO BAGS | K15: 7 | L15: MMM7 - Very remote community | M15: 0.6977 | N15: 7:69.8%; 6:28.8%; 5:1.2%; 2:0.2% | O15: 105190.33 | P15: 150775.8 | Q15: 7 | R15: MMM7 - Very remote community | S15: MMM 2023 (POA concordance) | V15: 25304 | W15: 17715 | X15: 70 | Y15: 601.6 | Z15: 1 | AA15: 5 | AB15: RA5 - Very remote Australia | AC15: Approximate: derived from Shipping_MMM via standard MMM→RA mapping | AD15: PHN701 | AE15: Northern Territory | AF15: 0.9995
A16: 828 | B16: NT | C16: 828|NT | D16: Berrimah | E16: Berrimah, Knuckey Lagoon | F16: 2 | G16: 2 | H16: =FALSE() | K16: 2 | L16: MMM2 - Regional centre | M16: 1 | N16: 2:100.0% | O16: 28.653 | P16: 28.6532 | Q16: 2 | R16: MMM2 - Regional centre | S16: MMM 2023 (POA concordance) | V16: 1697 | W16: 318 | X16: 18.7 | Y16: 989.3 | Z16: 5 | AA16: 2 | AB16: RA2 - Inner regional Australia | AC16: Approximate: derived from Shipping_MMM via standard MMM→RA mapping (MMM2-3 both map to RA2) | AD16: PHN701 | AE16: Northern Territory | AF16: 1
A17: 829 | B17: NT | C17: 829|NT | D17: Holtze | E17: Holtze, Pinelands | F17: 2 | G17: 2 | H17: =FALSE() | K17: 2 | L17: MMM2 - Regional centre | M17: 1 | N17: 2:100.0% | O17: 44.8404 | P17: 44.8402 | Q17: 2 | R17: MMM2 - Regional centre | S17: MMM 2023 (POA concordance) | V17: 1963 | W17: 942 | X17: 48 | Y17: 892.7 | Z17: 1 | AA17: 2 | AB17: RA2 - Inner regional Australia | AC17: Approximate: derived from Shipping_MMM via standard MMM→RA mapping (MMM2-3 both map to RA2) | AD17: PHN701 | AE17: Northern Territory | AF17: 1
A18: 830 | B18: NT | C18: 830|NT | D18: Archer | E18: Archer, Driver, Durack, Farrar, Gray | F18: 11 | G18: 11 | H18: =FALSE() | K18: 5 | L18: MMM5 - Small rural town | M18: 0.8754 | N18: 5:87.5%; 2:12.5% | O18: 205.717 | P18: 235.004 | Q18: 5 | R18: MMM5 - Small rural town | S18: MMM 2023 (POA concordance) | V18: 18501 | W18: 2856 | X18: 15.4 | Y18: 969.6 | Z18: 4 | AA18: 3 | AB18: RA3 - Outer regional Australia | AC18: Approximate: derived from Shipping_MMM via standard MMM→RA mapping (MMM4-5 both map to RA3; some MMM5 areas may be RA2) | AD18: PHN701 | AE18: Northern Territory | AF18: 1
A19: 831 | B19: NT | C19: 831|NT | D19: Palmerston | E19: Palmerston | F19: 1 | G19: 1 | H19: =TRUE() | I19: Post Office Boxes | J19: PO BOXES | Q19: 5 | R19: MMM5 - Small rural town | S19: No POA; assigned from nearest classified postcode | AA19: 3 | AB19: RA3 - Outer regional Australia | AC19: Approximate: derived from Shipping_MMM via standard MMM→RA mapping (MMM4-5 both map to RA3; some MMM5 areas may be RA2) | AD19: PHN701 | AE19: Northern Territory | AG19: Inferred (Single-state PHN)
A20: 832 | B20: NT | C20: 832|NT | D20: Bakewell | E20: Bakewell, Bellamack, Gunn, Johnston, Mitchell | F20: 7 | G20: 7 | H20: =FALSE() | K20: 2 | L20: MMM2 - Regional centre | M20: 1 | N20: 2:100.0% | O20: 19.7264 | P20: 19.7272 | Q20: 2 | R20: MMM2 - Regional centre | S20: MMM 2023 (POA concordance) | V20: 18727 | W20: 1981 | X20: 10.6 | Y20: 1048.4 | Z20: 8 | AA20: 2 | AB20: RA2 - Inner regional Australia | AC20: Approximate: derived from Shipping_MMM via standard MMM→RA mapping (MMM2-3 both map to RA2) | AD20: PHN701 | AE20: Northern Territory | AF20: 1
A21: 834 | B21: NT | C21: 834|NT | D21: Virginia | E21: Virginia | F21: 1 | G21: 1 | H21: =FALSE() | K21: 2 | L21: MMM2 - Regional centre | M21: 1 | N21: 2:100.0% | O21: 32.63 | P21: 32.6302 | Q21: 2 | R21: MMM2 - Regional centre | S21: MMM 2023 (POA concordance) | V21: 1811 | W21: 140 | X21: 7.7 | Y21: 1057.4 | Z21: 9 | AA21: 2 | AB21: RA2 - Inner regional Australia | AC21: Approximate: derived from Shipping_MMM via standard MMM→RA mapping (MMM2-3 both map to RA2) | AD21: PHN701 | AE21: Northern Territory | AF21: 1
A22: 835 | B22: NT | C22: 835|NT | D22: Howard Springs | E22: Howard Springs | F22: 1 | G22: 1 | H22: =FALSE() | K22: 2 | L22: MMM2 - Regional centre | M22: 1 | N22: 2:100.0% | O22: 76.8402 | P22: 76.8403 | Q22: 2 | R22: MMM2 - Regional centre | S22: MMM 2023 (POA concordance) | V22: 3153 | W22: 258 | X22: 8.2 | Y22: 1057.5 | Z22: 9 | AA22: 2 | AB22: RA2 - Inner regional Australia | AC22: Approximate: derived from Shipping_MMM via standard MMM→RA mapping (MMM2-3 both map to RA2) | AD22: PHN701 | AE22: Northern Territory | AF22: 1
A23: 836 | B23: NT | C23: 836|NT | D23: Girraween | E23: Girraween, Herbert, Humpty Doo | F23: 3 | G23: 3 | H23: =FALSE() | K23: 2 | L23: MMM2 - Regional centre | M23: 1 | N23: 2:100.0% | O23: 130.9305 | P23: 130.9305 | Q23: 2 | R23: MMM2 - Regional centre | S23: MMM 2023 (POA concordance) | V23: 7597 | W23: 607 | X23: 8 | Y23: 1044.2 | Z23: 8 | AA23: 2 | AB23: RA2 - Inner regional Australia | AC23: Approximate: derived from Shipping_MMM via standard MMM→RA mapping (MMM2-3 both map to RA2) | AD23: PHN701 | AE23: Northern Territory | AF23: 1
A24: 837 | B24: NT | C24: 837|NT | D24: Manton | E24: Manton, Noonamah | F24: 2 | G24: 2 | H24: =FALSE() | K24: 5 | L24: MMM5 - Small rural town | M24: 0.6401 | N24: 5:64.0%; 2:36.0% | O24: 83.7083 | P24: 130.7766 | Q24: 5 | R24: MMM5 - Small rural town | S24: MMM 2023 (POA concordance) | V24: 489 | W24: 94 | X24: 19.2 | Y24: 1011.2 | Z24: 6 | AA24: 3 | AB24: RA3 - Outer regional Australia | AC24: Approximate: derived from Shipping_MMM via standard MMM→RA mapping (MMM4-5 both map to RA3; some MMM5 areas may be RA2) | AD24: PHN701 | AE24: Northern Territory | AF24: 1
A25: 838 | B25: NT | C25: 838|NT | D25: Berry Springs | E25: Berry Springs | F25: 1 | G25: 1 | H25: =FALSE() | K25: 5 | L25: MMM5 - Small rural town | M25: 0.5467 | N25: 5:54.7%; 2:45.3% | O25: 47.2024 | P25: 86.3366 | Q25: 5 | R25: MMM5 - Small rural town | S25: MMM 2023 (POA concordance) | V25: 870 | W25: 74 | X25: 8.5 | Y25: 987.7 | Z25: 5 | AA25: 3 | AB25: RA3 - Outer regional Australia | AC25: Approximate: derived from Shipping_MMM via standard MMM→RA mapping (MMM4-5 both map to RA3; some MMM5 areas may be RA2) | AD25: PHN701 | AE25: Northern Territory | AF25: 1
A26: 839 | B26: NT | C26: 839|NT | D26: Coolalinga | E26: Coolalinga | F26: 1 | G26: 1 | H26: =FALSE() | K26: 2 | L26: MMM2 - Regional centre | M26: 1 | N26: 2:100.0% | O26: 1.1346 | P26: 1.1346 | Q26: 2 | R26: MMM2 - Regional centre | S26: MMM 2023 (POA concordance) | V26: 510 | W26: 59 | X26: 11.6 | Y26: 953 | Z26: 3 | AA26: 2 | AB26: RA2 - Inner regional Australia | AC26: Approximate: derived from Shipping_MMM via standard MMM→RA mapping (MMM2-3 both map to RA2) | AD26: PHN701 | AE26: Northern Territory | AF26: 1
A27: 840 | B27: NT | C27: 840|NT | D27: Dundee Beach | E27: Dundee Beach, Dundee Downs, Dundee Forest | F27: 3 | G27: 3 | H27: =FALSE() | K27: 6 | L27: MMM6 - Remote community | M27: 1 | N27: 6:100.0% | O27: 290.5634 | P27: 290.5631 | Q27: 6 | R27: MMM6 - Remote community | S27: MMM 2023 (POA concordance) | V27: 457 | W27: 49 | X27: 10.7 | Y27: 867.8 | Z27: 1 | AA27: 4 | AB27: RA4 - Remote Australia | AC27: Approximate: derived from Shipping_MMM via standard MMM→RA mapping | AD27: PHN701 | AE27: Northern Territory | AF27: 1
A28: 841 | B28: NT | C28: 841|NT | D28: Darwin River | E28: Darwin River | F28: 1 | G28: 1 | H28: =FALSE() | K28: 5 | L28: MMM5 - Small rural town | M28: 1 | N28: 5:100.0% | O28: 142.2065 | P28: 142.2064 | Q28: 5 | R28: MMM5 - Small rural town | S28: MMM 2023 (POA concordance) | V28: 627 | W28: 61 | X28: 9.7 | Y28: 969.3 | Z28: 4 | AA28: 3 | AB28: RA3 - Outer regional Australia | AC28: Approximate: derived from Shipping_MMM via standard MMM→RA mapping (MMM4-5 both map to RA3; some MMM5 areas may be RA2) | AD28: PHN701 | AE28: Northern Territory | AF28: 1
A29: 845 | B29: NT | C29: 845|NT | D29: Batchelor | E29: Batchelor | F29: 1 | G29: 1 | H29: =FALSE() | K29: 6 | L29: MMM6 - Remote community | M29: 1 | N29: 6:100.0% | O29: 115.696 | P29: 115.696 | Q29: 6 | R29: MMM6 - Remote community | S29: MMM 2023 (POA concordance) | V29: 396 | W29: 119 | X29: 30.1 | Y29: 801.6 | Z29: 1 | AA29: 4 | AB29: RA4 - Remote Australia | AC29: Approximate: derived from Shipping_MMM via standard MMM→RA mapping | AD29: PHN701 | AE29: Northern Territory | AF29: 1
A30: 846 | B30: NT | C30: 846|NT | D30: Adelaide River | E30: Adelaide River | F30: 1 | G30: 1 | H30: =FALSE() | K30: 6 | L30: MMM6 - Remote community | M30: 1 | N30: 6:100.0% | O30: 146.7378 | P30: 146.7377 | Q30: 6 | R30: MMM6 - Remote community | S30: MMM 2023 (POA concordance) | V30: 317 | W30: 83 | X30: 26.2 | Y30: 925.8 | Z30: 2 | AA30: 4 | AB30: RA4 - Remote Australia | AC30: Approximate: derived from Shipping_MMM via standard MMM→RA mapping | AD30: PHN701 | AE30: Northern Territory | AF30: 1
A31: 847 | B31: NT | C31: 847|NT | D31: Pine Creek | E31: Pine Creek | F31: 1 | G31: 1 | H31: =FALSE() | K31: 6 | L31: MMM6 - Remote community | M31: 1 | N31: 6:100.0% | O31: 402.0522 | P31: 402.0523 | Q31: 6 | R31: MMM6 - Remote community | S31: MMM 2023 (POA concordance) | V31: 318 | W31: 142 | X31: 44.7 | Y31: 793.4 | Z31: 1 | AA31: 4 | AB31: RA4 - Remote Australia | AC31: Approximate: derived from Shipping_MMM via standard MMM→RA mapping | AD31: PHN701 | AE31: Northern Territory | AF31: 1
A32: 850 | B32: NT | C32: 850|NT | D32: Cossack | E32: Cossack, Emungalan, Katherine, Katherine East, Katherine South | F32: 6 | G32: 6 | H32: =FALSE() | K32: 6 | L32: MMM6 - Remote community | M32: 1 | N32: 6:100.0% | O32: 551.1507 | P32: 551.1508 | Q32: 6 | R32: MMM6 - Remote community | S32: MMM 2023 (POA concordance) | V32: 7873 | W32: 2174 | X32: 27.6 | Y32: 954.4 | Z32: 3 | AA32: 4 | AB32: RA4 - Remote Australia | AC32: Approximate: derived from Shipping_MMM via standard MMM→RA mapping | AD32: PHN701 | AE32: Northern Territory | AF32: 1
